<robot name="simple_robot">
    <link name="base_link">
        <visual>
            <geometry>
                <sphere radius="0.25"/>
            </geometry>
            <material name="tab_green">
                <color rgba="0.173 0.627 0.173 1.0"/>
            </material>
        </visual>
    </link>

    <link name="link_0">
        <visual>
            <geometry>
                <box size="1 1 1"/>
            </geometry>
            <material name="ctu_blue">
                <color rgba="0.078 0.471 0.78 1.0"/>
            </material>
        </visual>
    </link>


    <joint name="joint0" type="prismatic">
        <origin xyz="0 0 1" rpy="0 0 0"/> <!-- Pose w.r.t. parent-->
        <parent link="base_link"/>
        <child link="link_0"/>
        <axis xyz="1 0 0"/>
        <limit effort="30" velocity="1.0" lower="-3.14" upper="3.14" />
    </joint>

</robot>
